<?xml version="1.0" encoding="utf-8"?>
<!-- This URDF was automatically created by SolidWorks to URDF Exporter! Originally created by Stephen Brawner (brawner@gmail.com) 
     Commit Version: 1.6.0-4-g7f85cfe  Build Version: 1.6.7995.38578
     For more information, please see http://wiki.ros.org/sw_urdf_exporter -->
<robot
  name="CRPArm610">
  <link
    name="base_link">
    <inertial>
      <origin
        xyz="-0.000674349286258242 -9.57651638712773E-05 -0.113518268732495"
        rpy="0 0 0" />
      <mass
        value="1.16368529234907" />
      <inertia
        ixx="0.00209625518197341"
        ixy="3.15964163333382E-06"
        ixz="-7.74213101526351E-07"
        iyy="0.00209018966735283"
        iyz="-5.67191106484566E-07"
        izz="0.0037142205211847" />
    </inertial>
    <visual>
      <origin
        xyz="0 0 0"
        rpy="0 0 0" />
      <geometry>
        <mesh
          filename="package://CRPArm610/meshes/base_link.STL" />
      </geometry>
      <material
        name="">
        <color
          rgba="1 1 1 1" />
      </material>
    </visual>
    <collision>
      <origin
        xyz="0 0 0"
        rpy="0 0 0" />
      <geometry>
        <mesh
          filename="package://CRPArm610/meshes/base_link.STL" />
      </geometry>
    </collision>
  </link>
  <link
    name="link1">
    <inertial>
      <origin
        xyz="-7.24583674363253E-08 0.00606183998684125 0.00627129705106724"
        rpy="0 0 0" />
      <mass
        value="1.87456055502344" />
      <inertia
        ixx="0.00316785881044048"
        ixy="1.24040391976572E-08"
        ixz="6.40446126711166E-09"
        iyy="0.0032047635184941"
        iyz="-0.000413904038987734"
        izz="0.0033774197790647" />
    </inertial>
    <visual>
      <origin
        xyz="0 0 0"
        rpy="0 0 0" />
      <geometry>
        <mesh
          filename="package://CRPArm610/meshes/link1.STL" />
      </geometry>
      <material
        name="">
        <color
          rgba="1 1 1 1" />
      </material>
    </visual>
    <collision>
      <origin
        xyz="0 0 0"
        rpy="0 0 0" />
      <geometry>
        <mesh
          filename="package://CRPArm610/meshes/link1.STL" />
      </geometry>
    </collision>
  </link>
  <joint
    name="joint1"
    type="revolute">
    <origin
      xyz="0 0 0"
      rpy="0 0 0" />
    <parent
      link="base_link" />
    <child
      link="link1" />
    <axis
      xyz="0 0 1" />
    <limit
      lower="-3.1416"
      upper="3.1416"
      effort="100"
      velocity="1" />
  </joint>
  <link
    name="link2">
    <inertial>
      <origin
        xyz="0.205141228414323 -1.86405305080406E-09 0.150491062634882"
        rpy="0 0 0" />
      <mass
        value="5.68539520514785" />
      <inertia
        ixx="0.00863399470527878"
        ixy="-2.50118887643864E-08"
        ixz="1.95365727793999E-11"
        iyy="0.0235156281739311"
        iyz="-6.24885572528394E-09"
        izz="0.0239276968366913" />
    </inertial>
    <visual>
      <origin
        xyz="0 0 0"
        rpy="0 0 0" />
      <geometry>
        <mesh
          filename="package://CRPArm610/meshes/link2.STL" />
      </geometry>
      <material
        name="">
        <color
          rgba="1 1 1 1" />
      </material>
    </visual>
    <collision>
      <origin
        xyz="0 0 0"
        rpy="0 0 0" />
      <geometry>
        <mesh
          filename="package://CRPArm610/meshes/link2.STL" />
      </geometry>
    </collision>
  </link>
  <joint
    name="joint2"
    type="revolute">
    <origin
      xyz="0 0 0"
      rpy="1.5708 0 -3.1416" />
    <parent
      link="link1" />
    <child
      link="link2" />
    <axis
      xyz="0 0 1" />
    <limit
      lower="-3.1416"
      upper="3.1416"
      effort="100"
      velocity="1" />
  </joint>
  <link
    name="link3">
    <inertial>
      <origin
        xyz="0.188307692060517 -4.4256491932293E-07 -0.00368033056201428"
        rpy="0 0 0" />
      <mass
        value="2.4859764237202" />
      <inertia
        ixx="0.00251731885497662"
        ixy="-1.13588288173413E-08"
        ixz="-0.00232630002492341"
        iyy="0.0228654103331224"
        iyz="-2.19699581700154E-09"
        izz="0.022774406706589" />
    </inertial>
    <visual>
      <origin
        xyz="0 0 0"
        rpy="0 0 0" />
      <geometry>
        <mesh
          filename="package://CRPArm610/meshes/link3.STL" />
      </geometry>
      <material
        name="">
        <color
          rgba="1 1 1 1" />
      </material>
    </visual>
    <collision>
      <origin
        xyz="0 0 0"
        rpy="0 0 0" />
      <geometry>
        <mesh
          filename="package://CRPArm610/meshes/link3.STL" />
      </geometry>
    </collision>
  </link>
  <joint
    name="joint3"
    type="revolute">
    <origin
      xyz="0.41059 0 0"
      rpy="-3.1416 0 1.5708" />
    <parent
      link="link2" />
    <child
      link="link3" />
    <axis
      xyz="0 0 1" />
    <limit
      lower="-3.1416"
      upper="3.1416"
      effort="100"
      velocity="1" />
  </joint>
  <link
    name="link4">
    <inertial>
      <origin
        xyz="-5.57666989253747E-08 0.00743847390057328 -0.00591229528332322"
        rpy="0 0 0" />
      <mass
        value="0.780053061638622" />
      <inertia
        ixx="0.000692719141646074"
        ixy="-2.57331975737178E-10"
        ixz="-1.61154328112677E-09"
        iyy="0.00074891283180327"
        iyz="9.01572433676218E-05"
        izz="0.000700124668981341" />
    </inertial>
    <visual>
      <origin
        xyz="0 0 0"
        rpy="0 0 0" />
      <geometry>
        <mesh
          filename="package://CRPArm610/meshes/link4.STL" />
      </geometry>
      <material
        name="">
        <color
          rgba="1 1 1 1" />
      </material>
    </visual>
    <collision>
      <origin
        xyz="0 0 0"
        rpy="0 0 0" />
      <geometry>
        <mesh
          filename="package://CRPArm610/meshes/link4.STL" />
      </geometry>
    </collision>
  </link>
  <joint
    name="joint4"
    type="revolute">
    <origin
      xyz="0.38348 0 -0.10438"
      rpy="3.1416 0 -1.5712" />
    <parent
      link="link3" />
    <child
      link="link4" />
    <axis
      xyz="0 0 1" />
    <limit
      lower="-3.1416"
      upper="3.1416"
      effort="100"
      velocity="1" />
  </joint>
  <link
    name="link5">
    <inertial>
      <origin
        xyz="-5.56952573227409E-08 0.00743847289686234 -0.00591229421880801"
        rpy="0 0 0" />
      <mass
        value="0.780053062528869" />
      <inertia
        ixx="0.000692719139988199"
        ixy="-2.56376346731032E-10"
        ixz="-1.60561233003251E-09"
        iyy="0.000748912825183739"
        iyz="9.01572405199701E-05"
        izz="0.000700124671233543" />
    </inertial>
    <visual>
      <origin
        xyz="0 0 0"
        rpy="0 0 0" />
      <geometry>
        <mesh
          filename="package://CRPArm610/meshes/link5.STL" />
      </geometry>
      <material
        name="">
        <color
          rgba="1 1 1 1" />
      </material>
    </visual>
    <collision>
      <origin
        xyz="0 0 0"
        rpy="0 0 0" />
      <geometry>
        <mesh
          filename="package://CRPArm610/meshes/link5.STL" />
      </geometry>
    </collision>
  </link>
  <joint
    name="joint5"
    type="revolute">
    <origin
      xyz="0 -0.11018 0"
      rpy="1.5708 -1.5708 0" />
    <parent
      link="link4" />
    <child
      link="link5" />
    <axis
      xyz="0 0 1" />
    <limit
      lower="-3.1416"
      upper="3.1416"
      effort="100"
      velocity="1" />
  </joint>
  <link
    name="link6">
    <inertial>
      <origin
        xyz="2.03777268006355E-05 -3.42185729751421E-09 -0.0303660993883046"
        rpy="0 0 0" />
      <mass
        value="0.286874661829911" />
      <inertia
        ixx="0.000167085211058213"
        ixy="6.16187324100708E-12"
        ixz="-1.83987422381629E-07"
        iyy="0.000167651422159989"
        iyz="-1.4337873992234E-11"
        izz="0.000251554427749969" />
    </inertial>
    <visual>
      <origin
        xyz="0 0 0"
        rpy="0 0 0" />
      <geometry>
        <mesh
          filename="package://CRPArm610/meshes/link6.STL" />
      </geometry>
      <material
        name="">
        <color
          rgba="1 1 1 1" />
      </material>
    </visual>
    <collision>
      <origin
        xyz="0 0 0"
        rpy="0 0 0" />
      <geometry>
        <mesh
          filename="package://CRPArm610/meshes/link6.STL" />
      </geometry>
    </collision>
  </link>
  <joint
    name="joint6"
    type="revolute">
    <origin
      xyz="0 -0.11245 5.0712E-05"
      rpy="0 1.5703 -1.5708" />
    <parent
      link="link5" />
    <child
      link="link6" />
    <axis
      xyz="0 0 1" />
    <limit
      lower="-3.1416"
      upper="3.1416"
      effort="100"
      velocity="1" />
  </joint>
</robot>