<?xml version="1.0" encoding="utf-8"?>
<!-- This URDF was automatically created by SolidWorks to URDF Exporter! Originally created by Stephen Brawner (brawner@gmail.com) 
     Commit Version: 1.6.0-4-g7f85cfe  Build Version: 1.6.7995.38578
     For more information, please see http://wiki.ros.org/sw_urdf_exporter -->
<robot
  name="CRPRobot222">
  <link
    name="base_link">
    <inertial>
      <origin
        xyz="-0.00067435 -9.5766E-05 -0.11352"
        rpy="0 0 0" />
      <mass
        value="1.1637" />
      <inertia
        ixx="0.0020963"
        ixy="3.1605E-06"
        ixz="-7.7421E-07"
        iyy="0.0020902"
        iyz="-5.672E-07"
        izz="0.0037142" />
    </inertial>
    <visual>
      <origin
        xyz="0 0 0"
        rpy="0 0 0" />
      <geometry>
        <mesh
          filename="package://CRPRobot222/meshes/base_link.STL" />
      </geometry>
      <material
        name="">
        <color
          rgba="1 1 1 1" />
      </material>
    </visual>
    <collision>
      <origin
        xyz="0 0 0"
        rpy="0 0 0" />
      <geometry>
        <mesh
          filename="package://CRPRobot222/meshes/base_link.STL" />
      </geometry>
    </collision>
  </link>
  <link
    name="link1">
    <inertial>
      <origin
        xyz="0.084471 6.7456E-08 -0.0060619"
        rpy="0 0 0" />
      <mass
        value="1.8746" />
      <inertia
        ixx="0.0033775"
        ixy="-2.2064E-08"
        ixz="0.00041382"
        iyy="0.003168"
        iyz="1.1102E-08"
        izz="0.0032048" />
    </inertial>
    <visual>
      <origin
        xyz="0 0 0"
        rpy="0 0 0" />
      <geometry>
        <mesh
          filename="package://CRPRobot222/meshes/link1.STL" />
      </geometry>
      <material
        name="">
        <color
          rgba="1 1 1 1" />
      </material>
    </visual>
    <collision>
      <origin
        xyz="0 0 0"
        rpy="0 0 0" />
      <geometry>
        <mesh
          filename="package://CRPRobot222/meshes/link1.STL" />
      </geometry>
    </collision>
  </link>
  <joint
    name="joint1"
    type="revolute">
    <origin
      xyz="0 0 -0.0782"
      rpy="1.5708 -1.5708 0" />
    <parent
      link="base_link" />
    <child
      link="link1" />
    <axis
      xyz="-1 0 0" />
    <limit
      lower="-3.1416"
      upper="3.1416"
      effort="100"
      velocity="1" />
  </joint>
  <link
    name="link2">
    <inertial>
      <origin
        xyz="0.079391 -0.20514 3.5247E-09"
        rpy="0 0 0" />
      <mass
        value="5.6854" />
      <inertia
        ixx="0.023928"
        ixy="-9.7011E-11"
        ixz="6.2501E-09"
        iyy="0.0086341"
        iyz="4.9659E-09"
        izz="0.023515" />
    </inertial>
    <visual>
      <origin
        xyz="0 0 0"
        rpy="0 0 0" />
      <geometry>
        <mesh
          filename="package://CRPRobot222/meshes/link2.STL" />
      </geometry>
      <material
        name="">
        <color
          rgba="1 1 1 1" />
      </material>
    </visual>
    <collision>
      <origin
        xyz="0 0 0"
        rpy="0 0 0" />
      <geometry>
        <mesh
          filename="package://CRPRobot222/meshes/link2.STL" />
      </geometry>
    </collision>
  </link>
  <joint
    name="joint2"
    type="revolute">
    <origin
      xyz="0.0782 0 -0.0711"
      rpy="1.5708 1.5708 0" />
    <parent
      link="link1" />
    <child
      link="link2" />
    <axis
      xyz="-1 0 0" />
    <limit
      lower="-3.1416"
      upper="3.1416"
      effort="100"
      velocity="1" />
  </joint>
  <link
    name="link3">
    <inertial>
      <origin
        xyz="0.07472 4.8306E-07 0.18831"
        rpy="0 0 0" />
      <mass
        value="2.4859" />
      <inertia
        ixx="0.022774"
        ixy="-4.3371E-08"
        ixz="-0.0023267"
        iyy="0.022866"
        iyz="9.3826E-08"
        izz="0.0025175" />
    </inertial>
    <visual>
      <origin
        xyz="0 0 0"
        rpy="0 0 0" />
      <geometry>
        <mesh
          filename="package://CRPRobot222/meshes/link3.STL" />
      </geometry>
      <material
        name="">
        <color
          rgba="1 1 1 1" />
      </material>
    </visual>
    <collision>
      <origin
        xyz="0 0 0"
        rpy="0 0 0" />
      <geometry>
        <mesh
          filename="package://CRPRobot222/meshes/link3.STL" />
      </geometry>
    </collision>
  </link>
  <joint
    name="joint3"
    type="revolute">
    <origin
      xyz="0.0073 -0.41059 0"
      rpy="3.1416 0 -3.1416" />
    <parent
      link="link2" />
    <child
      link="link3" />
    <axis
      xyz="1 0 0" />
    <limit
      lower="-3.1416"
      upper="3.1416"
      effort="100"
      velocity="1" />
  </joint>
  <link
    name="link4">
    <inertial>
      <origin
        xyz="0.0548687983314557 1.54682793018779E-07 -0.00743841619349239"
        rpy="0 0 0" />
      <mass
        value="0.780051566563787" />
      <inertia
        ixx="0.000700120605417098"
        ixy="-2.78837772668553E-10"
        ixz="-9.01582261662992E-05"
        iyy="0.000692721586582443"
        iyz="-8.2471486006598E-10"
        izz="0.000748911503862172" />
    </inertial>
    <visual>
      <origin
        xyz="0 0 0"
        rpy="0 0 0" />
      <geometry>
        <mesh
          filename="package://CRPRobot222/meshes/link4.STL" />
      </geometry>
      <material
        name="">
        <color
          rgba="1 1 1 1" />
      </material>
    </visual>
    <collision>
      <origin
        xyz="0 0 0"
        rpy="0 0 0" />
      <geometry>
        <mesh
          filename="package://CRPRobot222/meshes/link4.STL" />
      </geometry>
    </collision>
  </link>
  <joint
    name="joint4"
    type="revolute">
    <origin
      xyz="0.0348 0 0.38348"
      rpy="1.5708 0 -3.1416" />
    <parent
      link="link3" />
    <child
      link="link4" />
    <axis
      xyz="1 0 0" />
    <limit
      lower="-3.1416"
      upper="3.1416"
      effort="100"
      velocity="1" />
  </joint>
  <link
    name="link5">
    <inertial>
      <origin
        xyz="0.0548687153898499 1.71305170854064E-07 -0.00743855576381769"
        rpy="0 0 0" />
      <mass
        value="0.780050985723025" />
      <inertia
        ixx="0.000700124937467595"
        ixy="-7.68131158516808E-10"
        ixz="-9.01591263244589E-05"
        iyy="0.000692720674098957"
        iyz="-4.06999606515938E-10"
        izz="0.00074891264818209" />
    </inertial>
    <visual>
      <origin
        xyz="0 0 0"
        rpy="0 0 0" />
      <geometry>
        <mesh
          filename="package://CRPRobot222/meshes/link5.STL" />
      </geometry>
      <material
        name="">
        <color
          rgba="1 1 1 1" />
      </material>
    </visual>
    <collision>
      <origin
        xyz="0 0 0"
        rpy="0 0 0" />
      <geometry>
        <mesh
          filename="package://CRPRobot222/meshes/link5.STL" />
      </geometry>
    </collision>
  </link>
  <joint
    name="joint5"
    type="revolute">
    <origin
      xyz="0.060781 0 0.0494"
      rpy="1.5708 -1.5708 0" />
    <parent
      link="link4" />
    <child
      link="link5" />
    <axis
      xyz="1 0 0" />
    <limit
      lower="-3.1416"
      upper="3.1416"
      effort="100"
      velocity="1" />
  </joint>
  <link
    name="link6">
    <inertial>
      <origin
        xyz="0.0326842187721353 -1.54634001653942E-05 6.10160695035944E-06"
        rpy="0 0 0" />
      <mass
        value="0.286874900596623" />
      <inertia
        ixx="0.000251554468726418"
        ixy="-2.06509895906087E-07"
        ixz="8.17997686610074E-08"
        iyy="0.000167162252928583"
        iyz="1.93807890533889E-07"
        izz="0.000167574800564978" />
    </inertial>
    <visual>
      <origin
        xyz="0 0 0"
        rpy="0 0 0" />
      <geometry>
        <mesh
          filename="package://CRPRobot222/meshes/link6.STL" />
      </geometry>
      <material
        name="">
        <color
          rgba="1 1 1 1" />
      </material>
    </visual>
    <collision>
      <origin
        xyz="0 0 0"
        rpy="0 0 0" />
      <geometry>
        <mesh
          filename="package://CRPRobot222/meshes/link6.STL" />
      </geometry>
    </collision>
  </link>
  <joint
    name="joint6"
    type="revolute">
    <origin
      xyz="0.060781 0 0.0494"
      rpy="1.5708 -1.5708 0" />
    <parent
      link="link5" />
    <child
      link="link6" />
    <axis
      xyz="1 0 0" />
    <limit
      lower="-3.1416"
      upper="3.1416"
      effort="100"
      velocity="1" />
  </joint>
</robot>