<?xml version="1.0" encoding="utf-8"?>
<!-- This URDF was automatically created by SolidWorks to URDF Exporter! Originally created by Stephen Brawner (brawner@gmail.com) 
     Commit Version: 1.6.0-4-g7f85cfe  Build Version: 1.6.7995.38578
     For more information, please see http://wiki.ros.org/sw_urdf_exporter -->
<robot
  name="CRPArm611">
  <link
    name="base_link">
    <inertial>
      <origin
        xyz="-0.00067434928625806 -9.57651638712769E-05 -0.113518268732494"
        rpy="0 0 0" />
      <mass
        value="1.16368529234907" />
      <inertia
        ixx="0.00209625518197341"
        ixy="3.15964163334551E-06"
        ixz="-7.74213101520657E-07"
        iyy="0.00209018966681992"
        iyz="-5.6719110648469E-07"
        izz="0.00371422052065179" />
    </inertial>
    <visual>
      <origin
        xyz="0 0 0"
        rpy="0 0 0" />
      <geometry>
        <mesh
          filename="package://CRPArm611/meshes/base_link.STL" />
      </geometry>
      <material
        name="">
        <color
          rgba="1 1 1 1" />
      </material>
    </visual>
    <collision>
      <origin
        xyz="0 0 0"
        rpy="0 0 0" />
      <geometry>
        <mesh
          filename="package://CRPArm611/meshes/base_link.STL" />
      </geometry>
    </collision>
  </link>
  <link
    name="link1">
    <inertial>
      <origin
        xyz="-7.251136741507E-08 0.00606184001768607 0.00627129707813656"
        rpy="0 0 0" />
      <mass
        value="1.87456055573039" />
      <inertia
        ixx="0.00316785880189393"
        ixy="1.24090795185657E-08"
        ixz="6.40659643307612E-09"
        iyy="0.00320476352878857"
        iyz="-0.000413904039812656"
        izz="0.00337741978005272" />
    </inertial>
    <visual>
      <origin
        xyz="0 0 0"
        rpy="0 0 0" />
      <geometry>
        <mesh
          filename="package://CRPArm611/meshes/link1.STL" />
      </geometry>
      <material
        name="">
        <color
          rgba="1 1 1 1" />
      </material>
    </visual>
    <collision>
      <origin
        xyz="0 0 0"
        rpy="0 0 0" />
      <geometry>
        <mesh
          filename="package://CRPArm611/meshes/link1.STL" />
      </geometry>
    </collision>
  </link>
  <joint
    name="joint1"
    type="revolute">
    <origin
      xyz="0 0 0"
      rpy="0 0 0" />
    <parent
      link="base_link" />
    <child
      link="link1" />
    <axis
      xyz="0 0 1" />
    <limit
      lower="-3.1416"
      upper="3.1416"
      effort="100"
      velocity="1" />
  </joint>
  <link
    name="link2">
    <inertial>
      <origin
        xyz="0.20514123216365 1.63777896799999E-09 -0.150491062733097"
        rpy="0 0 0" />
      <mass
        value="5.68539521054905" />
      <inertia
        ixx="0.00863399478406122"
        ixy="2.49819989271267E-08"
        ixz="2.08852304939867E-11"
        iyy="0.0235156280778696"
        iyz="-6.23927769312602E-09"
        izz="0.0239276968548632" />
    </inertial>
    <visual>
      <origin
        xyz="0 0 0"
        rpy="0 0 0" />
      <geometry>
        <mesh
          filename="package://CRPArm611/meshes/link2.STL" />
      </geometry>
      <material
        name="">
        <color
          rgba="1 1 1 1" />
      </material>
    </visual>
    <collision>
      <origin
        xyz="0 0 0"
        rpy="0 0 0" />
      <geometry>
        <mesh
          filename="package://CRPArm611/meshes/link2.STL" />
      </geometry>
    </collision>
  </link>
  <joint
    name="joint2"
    type="revolute">
    <origin
      xyz="0 0 0"
      rpy="1.5708 0 0" />
    <parent
      link="link1" />
    <child
      link="link2" />
    <axis
      xyz="0 0 1" />
    <limit
      lower="-3.1416"
      upper="3.1416"
      effort="100"
      velocity="1" />
  </joint>
  <link
    name="link3">
    <inertial>
      <origin
        xyz="0.188307692022663 -4.42573359016318E-07 -0.00368033056555333"
        rpy="0 0 0" />
      <mass
        value="2.485976423272" />
      <inertia
        ixx="0.00251731885409736"
        ixy="-1.13589072810707E-08"
        ixz="-0.00232630002487258"
        iyy="0.0228654103332237"
        iyz="-2.19737746105039E-09"
        izz="0.0227744067060979" />
    </inertial>
    <visual>
      <origin
        xyz="0 0 0"
        rpy="0 0 0" />
      <geometry>
        <mesh
          filename="package://CRPArm611/meshes/link3.STL" />
      </geometry>
      <material
        name="">
        <color
          rgba="1 1 1 1" />
      </material>
    </visual>
    <collision>
      <origin
        xyz="0 0 0"
        rpy="0 0 0" />
      <geometry>
        <mesh
          filename="package://CRPArm611/meshes/link3.STL" />
      </geometry>
    </collision>
  </link>
  <joint
    name="joint3"
    type="revolute">
    <origin
      xyz="0.41059 0 0"
      rpy="0 0 -1.5708" />
    <parent
      link="link2" />
    <child
      link="link3" />
    <axis
      xyz="0 0 1" />
    <limit
      lower="-3.1416"
      upper="3.1416"
      effort="100"
      velocity="1" />
  </joint>
  <link
    name="link4">
    <inertial>
      <origin
        xyz="5.56126161788129E-08 0.00743847386949956 0.00591229531191241"
        rpy="0 0 0" />
      <mass
        value="0.780053062559751" />
      <inertia
        ixx="0.000692719143360077"
        ixy="2.55783270901763E-10"
        ixz="-1.60926234831647E-09"
        iyy="0.000748912832200911"
        iyz="-9.01572425512418E-05"
        izz="0.000700124670416063" />
    </inertial>
    <visual>
      <origin
        xyz="0 0 0"
        rpy="0 0 0" />
      <geometry>
        <mesh
          filename="package://CRPArm611/meshes/link4.STL" />
      </geometry>
      <material
        name="">
        <color
          rgba="1 1 1 1" />
      </material>
    </visual>
    <collision>
      <origin
        xyz="0 0 0"
        rpy="0 0 0" />
      <geometry>
        <mesh
          filename="package://CRPArm611/meshes/link4.STL" />
      </geometry>
    </collision>
  </link>
  <joint
    name="joint4"
    type="revolute">
    <origin
      xyz="0.38348 0 -0.10438"
      rpy="0 0 1.5703" />
    <parent
      link="link3" />
    <child
      link="link4" />
    <axis
      xyz="0 0 1" />
    <limit
      lower="-3.1416"
      upper="3.1416"
      effort="100"
      velocity="1" />
  </joint>
  <link
    name="link5">
    <inertial>
      <origin
        xyz="-5.57676931162154E-08 0.00743847372243589 -0.00591229530609361"
        rpy="0 0 0" />
      <mass
        value="0.780053060705608" />
      <inertia
        ixx="0.000692719139267504"
        ixy="-2.57053525187341E-10"
        ixz="-1.6065528754113E-09"
        iyy="0.000748912826114756"
        iyz="9.01572399889771E-05"
        izz="0.000700124665931359" />
    </inertial>
    <visual>
      <origin
        xyz="0 0 0"
        rpy="0 0 0" />
      <geometry>
        <mesh
          filename="package://CRPArm611/meshes/link5.STL" />
      </geometry>
      <material
        name="">
        <color
          rgba="1 1 1 1" />
      </material>
    </visual>
    <collision>
      <origin
        xyz="0 0 0"
        rpy="0 0 0" />
      <geometry>
        <mesh
          filename="package://CRPArm611/meshes/link5.STL" />
      </geometry>
    </collision>
  </link>
  <joint
    name="joint5"
    type="revolute">
    <origin
      xyz="0 -0.11018 0"
      rpy="1.5708 1.5708 0" />
    <parent
      link="link4" />
    <child
      link="link5" />
    <axis
      xyz="0 0 1" />
    <limit
      lower="-3.1416"
      upper="3.1416"
      effort="100"
      velocity="1" />
  </joint>
  <link
    name="link6">
    <inertial>
      <origin
        xyz="-3.67299304859792E-09 -2.03786932315708E-05 -0.0303660929956456"
        rpy="0 0 0" />
      <mass
        value="0.286874661829911" />
      <inertia
        ixx="0.000167651422160191"
        ixy="-6.16035172671926E-12"
        ixz="-1.36439689120061E-11"
        iyy="0.000167085211058416"
        iyz="1.83987422382697E-07"
        izz="0.00025155442774997" />
    </inertial>
    <visual>
      <origin
        xyz="0 0 0"
        rpy="0 0 0" />
      <geometry>
        <mesh
          filename="package://CRPArm611/meshes/link6.STL" />
      </geometry>
      <material
        name="">
        <color
          rgba="1 1 1 1" />
      </material>
    </visual>
    <collision>
      <origin
        xyz="0 0 0"
        rpy="0 0 0" />
      <geometry>
        <mesh
          filename="package://CRPArm611/meshes/link6.STL" />
      </geometry>
    </collision>
  </link>
  <joint
    name="joint6"
    type="revolute">
    <origin
      xyz="0 -0.11245 5.0714E-05"
      rpy="1.5703 0 0" />
    <parent
      link="link5" />
    <child
      link="link6" />
    <axis
      xyz="0 0 1" />
    <limit
      lower="-3.1416"
      upper="3.1416"
      effort="100"
      velocity="1" />
  </joint>
</robot>